Workbook

Sheet Ringkasan
A1: Saloka.id — Ringkasan Progres Fitur
A2: Snapshot 13 Sep 2026; baris Snackbox, Keranjang/Pelacakan Pesanan, DOKU, Biteship, dan modul Komunitas 6.c.xv–xxiv diverifikasi ulang 30 Sep 2026. Angka diperbarui otomatis ketika status diubah di sheet “Pelacak Fitur”.
A4: Fitur | B4: Status keseluruhan | C4: Ringkasan | D4: Halaman / tab yang dilacak | E4: Selesai | F4: Quality Check | G4: Sedang Berjalan | H4: Belum Dimulai | I4: % Selesai | J4: % Selesai atau dalam QC
A5: Halaman Utama & Pencarian | B5: =INDEX('Pelacak Fitur'!$E:$E,MATCH($A5,'Pelacak Fitur'!$D:$D,0)) | C5: =INDEX('Pelacak Fitur'!$F:$F,MATCH($A5,'Pelacak Fitur'!$D:$D,0)) | D5: =COUNTIFS('Pelacak Fitur'!$B:$B,$A5,'Pelacak Fitur'!$C:$C,"<>Fitur") | E5: =COUNTIFS('Pelacak Fitur'!$B:$B,$A5,'Pelacak Fitur'!$C:$C,"<>Fitur",'Pelacak Fitur'!$E:$E,"Selesai") | F5: =COUNTIFS('Pelacak Fitur'!$B:$B,$A5,'Pelacak Fitur'!$C:$C,"<>Fitur",'Pelacak Fitur'!$E:$E,"Quality Check") | G5: =COUNTIFS('Pelacak Fitur'!$B:$B,$A5,'Pelacak Fitur'!$C:$C,"<>Fitur",'Pelacak Fitur'!$E:$E,"Sedang Berjalan") | H5: =COUNTIFS('Pelacak Fitur'!$B:$B,$A5,'Pelacak Fitur'!$C:$C,"<>Fitur",'Pelacak Fitur'!$E:$E,"Belum Dimulai") | I5: =IF(D5=0,"",E5/D5) | J5: =IF(D5=0,"",(E5+F5)/D5)
A6: Akun & Identitas | B6: =INDEX('Pelacak Fitur'!$E:$E,MATCH($A6,'Pelacak Fitur'!$D:$D,0)) | C6: =INDEX('Pelacak Fitur'!$F:$F,MATCH($A6,'Pelacak Fitur'!$D:$D,0)) | D6: =COUNTIFS('Pelacak Fitur'!$B:$B,$A6,'Pelacak Fitur'!$C:$C,"<>Fitur") | E6: =COUNTIFS('Pelacak Fitur'!$B:$B,$A6,'Pelacak Fitur'!$C:$C,"<>Fitur",'Pelacak Fitur'!$E:$E,"Selesai") | F6: =COUNTIFS('Pelacak Fitur'!$B:$B,$A6,'Pelacak Fitur'!$C:$C,"<>Fitur",'Pelacak Fitur'!$E:$E,"Quality Check") | G6: =COUNTIFS('Pelacak Fitur'!$B:$B,$A6,'Pelacak Fitur'!$C:$C,"<>Fitur",'Pelacak Fitur'!$E:$E,"Sedang Berjalan") | H6: =COUNTIFS('Pelacak Fitur'!$B:$B,$A6,'Pelacak Fitur'!$C:$C,"<>Fitur",'Pelacak Fitur'!$E:$E,"Belum Dimulai") | I6: =IF(D6=0,"",E6/D6) | J6: =IF(D6=0,"",(E6+F6)/D6)
A7: Marketplace (Produk) | B7: =INDEX('Pelacak Fitur'!$E:$E,MATCH($A7,'Pelacak Fitur'!$D:$D,0)) | C7: =INDEX('Pelacak Fitur'!$F:$F,MATCH($A7,'Pelacak Fitur'!$D:$D,0)) | D7: =COUNTIFS('Pelacak Fitur'!$B:$B,$A7,'Pelacak Fitur'!$C:$C,"<>Fitur") | E7: =COUNTIFS('Pelacak Fitur'!$B:$B,$A7,'Pelacak Fitur'!$C:$C,"<>Fitur",'Pelacak Fitur'!$E:$E,"Selesai") | F7: =COUNTIFS('Pelacak Fitur'!$B:$B,$A7,'Pelacak Fitur'!$C:$C,"<>Fitur",'Pelacak Fitur'!$E:$E,"Quality Check") | G7: =COUNTIFS('Pelacak Fitur'!$B:$B,$A7,'Pelacak Fitur'!$C:$C,"<>Fitur",'Pelacak Fitur'!$E:$E,"Sedang Berjalan") | H7: =COUNTIFS('Pelacak Fitur'!$B:$B,$A7,'Pelacak Fitur'!$C:$C,"<>Fitur",'Pelacak Fitur'!$E:$E,"Belum Dimulai") | I7: =IF(D7=0,"",E7/D7) | J7: =IF(D7=0,"",(E7+F7)/D7)
A8: Jasa | B8: =INDEX('Pelacak Fitur'!$E:$E,MATCH($A8,'Pelacak Fitur'!$D:$D,0)) | C8: =INDEX('Pelacak Fitur'!$F:$F,MATCH($A8,'Pelacak Fitur'!$D:$D,0)) | D8: =COUNTIFS('Pelacak Fitur'!$B:$B,$A8,'Pelacak Fitur'!$C:$C,"<>Fitur") | E8: =COUNTIFS('Pelacak Fitur'!$B:$B,$A8,'Pelacak Fitur'!$C:$C,"<>Fitur",'Pelacak Fitur'!$E:$E,"Selesai") | F8: =COUNTIFS('Pelacak Fitur'!$B:$B,$A8,'Pelacak Fitur'!$C:$C,"<>Fitur",'Pelacak Fitur'!$E:$E,"Quality Check") | G8: =COUNTIFS('Pelacak Fitur'!$B:$B,$A8,'Pelacak Fitur'!$C:$C,"<>Fitur",'Pelacak Fitur'!$E:$E,"Sedang Berjalan") | H8: =COUNTIFS('Pelacak Fitur'!$B:$B,$A8,'Pelacak Fitur'!$C:$C,"<>Fitur",'Pelacak Fitur'!$E:$E,"Belum Dimulai") | I8: =IF(D8=0,"",E8/D8) | J8: =IF(D8=0,"",(E8+F8)/D8)
A9: Snackbox | B9: =INDEX('Pelacak Fitur'!$E:$E,MATCH($A9,'Pelacak Fitur'!$D:$D,0)) | C9: =INDEX('Pelacak Fitur'!$F:$F,MATCH($A9,'Pelacak Fitur'!$D:$D,0)) | D9: =COUNTIFS('Pelacak Fitur'!$B:$B,$A9,'Pelacak Fitur'!$C:$C,"<>Fitur") | E9: =COUNTIFS('Pelacak Fitur'!$B:$B,$A9,'Pelacak Fitur'!$C:$C,"<>Fitur",'Pelacak Fitur'!$E:$E,"Selesai") | F9: =COUNTIFS('Pelacak Fitur'!$B:$B,$A9,'Pelacak Fitur'!$C:$C,"<>Fitur",'Pelacak Fitur'!$E:$E,"Quality Check") | G9: =COUNTIFS('Pelacak Fitur'!$B:$B,$A9,'Pelacak Fitur'!$C:$C,"<>Fitur",'Pelacak Fitur'!$E:$E,"Sedang Berjalan") | H9: =COUNTIFS('Pelacak Fitur'!$B:$B,$A9,'Pelacak Fitur'!$C:$C,"<>Fitur",'Pelacak Fitur'!$E:$E,"Belum Dimulai") | I9: =IF(D9=0,"",E9/D9) | J9: =IF(D9=0,"",(E9+F9)/D9)
A10: Komunitas | B10: =INDEX('Pelacak Fitur'!$E:$E,MATCH($A10,'Pelacak Fitur'!$D:$D,0)) | C10: =INDEX('Pelacak Fitur'!$F:$F,MATCH($A10,'Pelacak Fitur'!$D:$D,0)) | D10: =COUNTIFS('Pelacak Fitur'!$B:$B,$A10,'Pelacak Fitur'!$C:$C,"<>Fitur") | E10: =COUNTIFS('Pelacak Fitur'!$B:$B,$A10,'Pelacak Fitur'!$C:$C,"<>Fitur",'Pelacak Fitur'!$E:$E,"Selesai") | F10: =COUNTIFS('Pelacak Fitur'!$B:$B,$A10,'Pelacak Fitur'!$C:$C,"<>Fitur",'Pelacak Fitur'!$E:$E,"Quality Check") | G10: =COUNTIFS('Pelacak Fitur'!$B:$B,$A10,'Pelacak Fitur'!$C:$C,"<>Fitur",'Pelacak Fitur'!$E:$E,"Sedang Berjalan") | H10: =COUNTIFS('Pelacak Fitur'!$B:$B,$A10,'Pelacak Fitur'!$C:$C,"<>Fitur",'Pelacak Fitur'!$E:$E,"Belum Dimulai") | I10: =IF(D10=0,"",E10/D10) | J10: =IF(D10=0,"",(E10+F10)/D10)
A11: Pembayaran, Wallet & Koin | B11: =INDEX('Pelacak Fitur'!$E:$E,MATCH($A11,'Pelacak Fitur'!$D:$D,0)) | C11: =INDEX('Pelacak Fitur'!$F:$F,MATCH($A11,'Pelacak Fitur'!$D:$D,0)) | D11: =COUNTIFS('Pelacak Fitur'!$B:$B,$A11,'Pelacak Fitur'!$C:$C,"<>Fitur") | E11: =COUNTIFS('Pelacak Fitur'!$B:$B,$A11,'Pelacak Fitur'!$C:$C,"<>Fitur",'Pelacak Fitur'!$E:$E,"Selesai") | F11: =COUNTIFS('Pelacak Fitur'!$B:$B,$A11,'Pelacak Fitur'!$C:$C,"<>Fitur",'Pelacak Fitur'!$E:$E,"Quality Check") | G11: =COUNTIFS('Pelacak Fitur'!$B:$B,$A11,'Pelacak Fitur'!$C:$C,"<>Fitur",'Pelacak Fitur'!$E:$E,"Sedang Berjalan") | H11: =COUNTIFS('Pelacak Fitur'!$B:$B,$A11,'Pelacak Fitur'!$C:$C,"<>Fitur",'Pelacak Fitur'!$E:$E,"Belum Dimulai") | I11: =IF(D11=0,"",E11/D11) | J11: =IF(D11=0,"",(E11+F11)/D11)
A12: Alat Merchant & Storefront | B12: =INDEX('Pelacak Fitur'!$E:$E,MATCH($A12,'Pelacak Fitur'!$D:$D,0)) | C12: =INDEX('Pelacak Fitur'!$F:$F,MATCH($A12,'Pelacak Fitur'!$D:$D,0)) | D12: =COUNTIFS('Pelacak Fitur'!$B:$B,$A12,'Pelacak Fitur'!$C:$C,"<>Fitur") | E12: =COUNTIFS('Pelacak Fitur'!$B:$B,$A12,'Pelacak Fitur'!$C:$C,"<>Fitur",'Pelacak Fitur'!$E:$E,"Selesai") | F12: =COUNTIFS('Pelacak Fitur'!$B:$B,$A12,'Pelacak Fitur'!$C:$C,"<>Fitur",'Pelacak Fitur'!$E:$E,"Quality Check") | G12: =COUNTIFS('Pelacak Fitur'!$B:$B,$A12,'Pelacak Fitur'!$C:$C,"<>Fitur",'Pelacak Fitur'!$E:$E,"Sedang Berjalan") | H12: =COUNTIFS('Pelacak Fitur'!$B:$B,$A12,'Pelacak Fitur'!$C:$C,"<>Fitur",'Pelacak Fitur'!$E:$E,"Belum Dimulai") | I12: =IF(D12=0,"",E12/D12) | J12: =IF(D12=0,"",(E12+F12)/D12)
A13: Affiliate | B13: =INDEX('Pelacak Fitur'!$E:$E,MATCH($A13,'Pelacak Fitur'!$D:$D,0)) | C13: =INDEX('Pelacak Fitur'!$F:$F,MATCH($A13,'Pelacak Fitur'!$D:$D,0)) | D13: =COUNTIFS('Pelacak Fitur'!$B:$B,$A13,'Pelacak Fitur'!$C:$C,"<>Fitur") | E13: =COUNTIFS('Pelacak Fitur'!$B:$B,$A13,'Pelacak Fitur'!$C:$C,"<>Fitur",'Pelacak Fitur'!$E:$E,"Selesai") | F13: =COUNTIFS('Pelacak Fitur'!$B:$B,$A13,'Pelacak Fitur'!$C:$C,"<>Fitur",'Pelacak Fitur'!$E:$E,"Quality Check") | G13: =COUNTIFS('Pelacak Fitur'!$B:$B,$A13,'Pelacak Fitur'!$C:$C,"<>Fitur",'Pelacak Fitur'!$E:$E,"Sedang Berjalan") | H13: =COUNTIFS('Pelacak Fitur'!$B:$B,$A13,'Pelacak Fitur'!$C:$C,"<>Fitur",'Pelacak Fitur'!$E:$E,"Belum Dimulai") | I13: =IF(D13=0,"",E13/D13) | J13: =IF(D13=0,"",(E13+F13)/D13)
A14: Academy (LMS) | B14: =INDEX('Pelacak Fitur'!$E:$E,MATCH($A14,'Pelacak Fitur'!$D:$D,0)) | C14: =INDEX('Pelacak Fitur'!$F:$F,MATCH($A14,'Pelacak Fitur'!$D:$D,0)) | D14: =COUNTIFS('Pelacak Fitur'!$B:$B,$A14,'Pelacak Fitur'!$C:$C,"<>Fitur") | E14: =COUNTIFS('Pelacak Fitur'!$B:$B,$A14,'Pelacak Fitur'!$C:$C,"<>Fitur",'Pelacak Fitur'!$E:$E,"Selesai") | F14: =COUNTIFS('Pelacak Fitur'!$B:$B,$A14,'Pelacak Fitur'!$C:$C,"<>Fitur",'Pelacak Fitur'!$E:$E,"Quality Check") | G14: =COUNTIFS('Pelacak Fitur'!$B:$B,$A14,'Pelacak Fitur'!$C:$C,"<>Fitur",'Pelacak Fitur'!$E:$E,"Sedang Berjalan") | H14: =COUNTIFS('Pelacak Fitur'!$B:$B,$A14,'Pelacak Fitur'!$C:$C,"<>Fitur",'Pelacak Fitur'!$E:$E,"Belum Dimulai") | I14: =IF(D14=0,"",E14/D14) | J14: =IF(D14=0,"",(E14+F14)/D14)
A15: Chat & Layanan Pelanggan (CS) | B15: =INDEX('Pelacak Fitur'!$E:$E,MATCH($A15,'Pelacak Fitur'!$D:$D,0)) | C15: =INDEX('Pelacak Fitur'!$F:$F,MATCH($A15,'Pelacak Fitur'!$D:$D,0)) | D15: =COUNTIFS('Pelacak Fitur'!$B:$B,$A15,'Pelacak Fitur'!$C:$C,"<>Fitur") | E15: =COUNTIFS('Pelacak Fitur'!$B:$B,$A15,'Pelacak Fitur'!$C:$C,"<>Fitur",'Pelacak Fitur'!$E:$E,"Selesai") | F15: =COUNTIFS('Pelacak Fitur'!$B:$B,$A15,'Pelacak Fitur'!$C:$C,"<>Fitur",'Pelacak Fitur'!$E:$E,"Quality Check") | G15: =COUNTIFS('Pelacak Fitur'!$B:$B,$A15,'Pelacak Fitur'!$C:$C,"<>Fitur",'Pelacak Fitur'!$E:$E,"Sedang Berjalan") | H15: =COUNTIFS('Pelacak Fitur'!$B:$B,$A15,'Pelacak Fitur'!$C:$C,"<>Fitur",'Pelacak Fitur'!$E:$E,"Belum Dimulai") | I15: =IF(D15=0,"",E15/D15) | J15: =IF(D15=0,"",(E15+F15)/D15)
A16: Admin CMS (Platform) | B16: =INDEX('Pelacak Fitur'!$E:$E,MATCH($A16,'Pelacak Fitur'!$D:$D,0)) | C16: =INDEX('Pelacak Fitur'!$F:$F,MATCH($A16,'Pelacak Fitur'!$D:$D,0)) | D16: =COUNTIFS('Pelacak Fitur'!$B:$B,$A16,'Pelacak Fitur'!$C:$C,"<>Fitur") | E16: =COUNTIFS('Pelacak Fitur'!$B:$B,$A16,'Pelacak Fitur'!$C:$C,"<>Fitur",'Pelacak Fitur'!$E:$E,"Selesai") | F16: =COUNTIFS('Pelacak Fitur'!$B:$B,$A16,'Pelacak Fitur'!$C:$C,"<>Fitur",'Pelacak Fitur'!$E:$E,"Quality Check") | G16: =COUNTIFS('Pelacak Fitur'!$B:$B,$A16,'Pelacak Fitur'!$C:$C,"<>Fitur",'Pelacak Fitur'!$E:$E,"Sedang Berjalan") | H16: =COUNTIFS('Pelacak Fitur'!$B:$B,$A16,'Pelacak Fitur'!$C:$C,"<>Fitur",'Pelacak Fitur'!$E:$E,"Belum Dimulai") | I16: =IF(D16=0,"",E16/D16) | J16: =IF(D16=0,"",(E16+F16)/D16)
A17: Halaman Legal | B17: =INDEX('Pelacak Fitur'!$E:$E,MATCH($A17,'Pelacak Fitur'!$D:$D,0)) | C17: =INDEX('Pelacak Fitur'!$F:$F,MATCH($A17,'Pelacak Fitur'!$D:$D,0)) | D17: =COUNTIFS('Pelacak Fitur'!$B:$B,$A17,'Pelacak Fitur'!$C:$C,"<>Fitur") | E17: =COUNTIFS('Pelacak Fitur'!$B:$B,$A17,'Pelacak Fitur'!$C:$C,"<>Fitur",'Pelacak Fitur'!$E:$E,"Selesai") | F17: =COUNTIFS('Pelacak Fitur'!$B:$B,$A17,'Pelacak Fitur'!$C:$C,"<>Fitur",'Pelacak Fitur'!$E:$E,"Quality Check") | G17: =COUNTIFS('Pelacak Fitur'!$B:$B,$A17,'Pelacak Fitur'!$C:$C,"<>Fitur",'Pelacak Fitur'!$E:$E,"Sedang Berjalan") | H17: =COUNTIFS('Pelacak Fitur'!$B:$B,$A17,'Pelacak Fitur'!$C:$C,"<>Fitur",'Pelacak Fitur'!$E:$E,"Belum Dimulai") | I17: =IF(D17=0,"",E17/D17) | J17: =IF(D17=0,"",(E17+F17)/D17)
A18: TOTAL | D18: =SUM(D5:D17) | E18: =SUM(E5:E17) | F18: =SUM(F5:F17) | G18: =SUM(G5:G17) | H18: =SUM(H5:H17) | I18: =IF(D18=0,"",E18/D18) | J18: =IF(D18=0,"",(E18+F18)/D18)

Sheet Pelacak Fitur
A1: FITUR & HALAMAN | G1: DETAIL | P1: PELACAKAN | T1: ITERASI 1 · S.D. 22 AGU 2026 (HANYA PERBAIKAN BESAR) | X1: ITERASI 2 · 23–31 AGU 2026 | AB1: ITERASI 3 · 1–6 SEP 2026 (MINGGU A) | AF1: ITERASI 4 · 7–13 SEP 2026 (MINGGU B)
A2: No. | B2: Fitur | C2: Level | D2: Nama | E2: Status | F2: Alasan status (hasil inferensi) | G2: Link (saloka.id) | H2: Siapa yang bisa akses | I2: Fungsi | J2: Data yang ditampilkan / disimpan | K2: Tabel database | L2: Server action & API endpoint | M2: File kode utama | N2: Roadmap Sept 2026 | O2: Kekurangan / isu terbuka | P2: Pertama dibuat (git) | Q2: Terakhir diubah (git) | R2: PIC | S2: Target tanggal | T2: Bug ditemukan | U2: Tanggal ditemukan | V2: Perbaikan | W2: Tanggal perbaikan | X2: Bug ditemukan | Y2: Tanggal ditemukan | Z2: Perbaikan | AA2: Tanggal perbaikan | AB2: Bug ditemukan | AC2: Tanggal ditemukan | AD2: Perbaikan | AE2: Tanggal perbaikan | AF2: Bug ditemukan | AG2: Tanggal ditemukan | AH2: Perbaikan | AI2: Tanggal perbaikan
A3: 1 | B3: Halaman Utama & Pencarian | C3: Fitur | D3: Halaman Utama & Pencarian | E3: Quality Check | F3: Berjalan dengan data asli; halaman utama diubah 13 Sep; penyempurnaan notifikasi masih ada di roadmap.
A4: 1.a | B4: Halaman Utama & Pencarian | C4: Halaman | D4: Halaman Utama | E4: Quality Check | F4: Diubah 13 Sep; kartu komunitas contoh masih dipakai sebagai cadangan. | G4: https://saloka.id/ | H4: Semua orang (publik) | I4: Halaman masuk utama: carousel banner promo, sorotan produk dan jasa, kartu komunitas, ikon aksi cepat. | J4: Banner promo aktif, produk, jasa, komunitas (dan komunitas yang sudah diikuti pengunjung) | K4: LandingBanner, Product, Service, Community, CommunityMembership, User | L4: landing.getActiveBanners; products.getProducts; services.getServicesAction; community.getIndukCommunities; auth.getCurrentUser | M4: src/app/page.tsx; src/app/components/HomeExplorer.tsx; src/app/components/BannerCarousel.tsx | O4: Menampilkan 3 kartu komunitas contoh yang di-hardcode (comm-dummy-1..3) jika tidak ada komunitas yang termuat. | P4: 2026-05-23 | Q4: 2026-09-13
A5: 1.b | B5: Halaman Utama & Pencarian | C5: Komponen | D5: Pencarian global (navbar) | E5: Selesai | F5: Data asli; dirilis 25–31 Agu; tidak ada perbaikan bug sejak itu. | G5: Navbar di setiap halaman → /market?q=… , /jasa?search=… | H5: Semua orang | I5: Pencarian instan dengan autocomplete untuk produk, jasa, dan komunitas, dengan rekomendasi jika tidak ada hasil. | J5: Produk, jasa, komunitas yang cocok dengan kata kunci | K5: Product, Service, Community | L5: search.searchGlobalAction | M5: src/app/actions/search.ts; src/app/components/HeaderNavigation.tsx | P5: 2026-08-29 | Q5: 2026-08-29
A6: 1.c | B6: Halaman Utama & Pencarian | C6: Komponen | D6: Lonceng notifikasi | E6: Quality Check | F6: Berjalan dengan data asli; roadmap Minggu B masih mencantumkan penyempurnaan notifikasi. | G6: Navbar (setelah login) | H6: Pengguna yang sudah login | I6: Notifikasi dalam aplikasi (update pesanan, aktivitas komunitas, balasan). | J6: Notifikasi per pengguna, sudah/belum dibaca | K6: Notification | L6: GET/POST /api/notifications | M6: src/app/components/NotificationBell.tsx; src/app/api/notifications/route.ts | N6: Minggu B: menyempurnakan sistem notifikasi | P6: 2026-05-31 | Q6: 2026-08-29
A7: 2 | B7: Akun & Identitas | C7: Fitur | D7: Akun & Identitas | E7: Quality Check | F7: Keamanan login dan atribusi referral dibangun ulang 13 Sep; KYC masih punya jalur uji coba/bypass.
A8: 2.a | B8: Akun & Identitas | C8: Halaman | D8: Login & Daftar | E8: Quality Check | F8: Rate limiting dibangun ulang 13 Sep; perlu diuji ulang. | G8: https://saloka.id/auth?tab=login | H8: Semua orang | I8: Login & pendaftaran dengan email/password (password di-hash bcrypt), login Google, percobaan login dibatasi (rate limit); logout menghapus cookie sesi di semua domain Saloka. | J8: Kredensial akun, cookie sesi, percobaan login gagal | K8: User, Wallet, RateLimitAttempt, AuditLog | L8: auth.login / register / logout; /api/auth/google/callback; /api/auth/check-username; /api/auth/logout; /api/auth/clear-cookies | M8: src/app/auth/page.tsx; src/components/AuthForm.tsx; src/app/actions/auth.ts; src/lib/rate-limit.ts | N8: Jalur paralel: Sistem Verifikasi, ISO 27001 | P8: 2026-05-30 | Q8: 2026-09-13 | T8: Logout meninggalkan cookie sesi di domain Saloka lain (pengguna tetap login) | U8: — | V8: Route logout menghapus cookie di semua domain (15dc8d4, ce7be98, fcf422c) | W8: 2026-07-22 | AF8: Rate limit login ter-reset per instance server (risiko brute-force) | AG8: — | AH8: Rate limiting disimpan di database (1c4c28b) | AI8: 2026-09-13
A9: 2.b | B9: Akun & Identitas | C9: Halaman | D9: Pilih peran akun | E9: Selesai | F9: Tidak berubah sejak 18 Jul; tidak ditemukan masalah terbuka di kode. | G9: https://saloka.id/auth/select-role | H9: Pengguna yang baru mendaftar | I9: Memilih jenis akun setelah mendaftar. | J9: Peran pengguna | K9: User | L9: auth.selectUserRole | M9: src/app/auth/select-role/page.tsx | P9: 2026-07-18 | Q9: 2026-07-18
A10: 2.c | B10: Akun & Identitas | C10: Halaman | D10: Lupa password | E10: Quality Check | F10: Dibuat 1 Sep; belum ada catatan QA. | G10: https://saloka.id/forgot-password | H10: Semua orang | I10: Reset password dengan kode sekali pakai. | J10: Kode reset, hash password baru | K10: User | L10: auth.requestPasswordReset; auth.resetPasswordWithOtp | M10: src/app/forgot-password/page.tsx | P10: 2026-09-01 | Q10: 2026-09-01
A11: 2.d | B11: Akun & Identitas | C11: Halaman | D11: Onboarding | E11: Quality Check | F11: Terakhir diubah 1 Sep; belum ada catatan QA. | G11: https://saloka.id/onboarding | H11: Pengguna yang sudah login tetapi belum menyelesaikan pengaturan awal | I11: Pengaturan bertahap: verifikasi nomor HP/email dengan OTP, tambah alamat, buat subdomain toko (merchant). | J11: Verifikasi HP & email, alamat, subdomain | K11: User | L11: auth.saveOnboardingData, checkSubdomainAvailability, sendPhoneVerificationOtp, verifyPhoneOtp, sendEmailVerificationOtp, verifyEmailOtp, checkWhatsAppUnique | M11: src/app/onboarding/page.tsx; src/app/components/OnboardingGuard.tsx | P11: 2026-06-07 | Q11: 2026-09-01
A12: 2.e | B12: Akun & Identitas | C12: Halaman | D12: Pengaturan akun | E12: Quality Check | F12: Diubah 9 Sep. | G12: https://saloka.id/settings | H12: Pengguna yang sudah login | I12: Pusat pengaturan akun dengan 8 tab (di bawah). | J12: Profil, keamanan, KYC, referral, alamat, WhatsApp gateway, preferensi notifikasi & tampilan | K12: User, Wallet | L12: auth.updateUsernameAction, getReferralInfo; wallet-affiliate.updateUserSettingsAction, getWaLogsAction; /api/kyc/didit, /api/kyc/status, /api/kyc/simulate; /api/upload | M12: src/app/settings/page.tsx | P12: 2026-06-09 | Q12: 2026-09-09
A13: 2.e.i | B13: Akun & Identitas | C13: Tab | D13: Profil & Biodata | E13: Quality Check | F13: Bagian dari Pengaturan akun (diubah 9 Sep). | G13: https://saloka.id/settings (tab dipilih di dalam halaman) | H13: Pengguna yang sudah login | I13: Nama, foto (upload), dan bio. | M13: src/app/settings/page.tsx | P13: 2026-06-09 | Q13: 2026-09-09
A14: 2.e.ii | B14: Akun & Identitas | C14: Tab | D14: Akun & Keamanan | E14: Quality Check | F14: Bagian dari Pengaturan akun (diubah 9 Sep). | G14: https://saloka.id/settings (tab dipilih di dalam halaman) | H14: Pengguna yang sudah login | I14: Username, password, nomor HP, dan email. | M14: src/app/settings/page.tsx | P14: 2026-06-09 | Q14: 2026-09-09
A15: 2.e.iii | B15: Akun & Identitas | C15: Tab | D15: Verifikasi Identitas (KYC) | E15: Quality Check | F15: Bagian dari Pengaturan akun (diubah 9 Sep). | G15: https://saloka.id/settings (tab dipilih di dalam halaman) | H15: Pengguna yang sudah login | I15: Memulai verifikasi identitas dengan Didit dan melihat statusnya. | M15: src/app/settings/page.tsx | O15: Pemanggilan KYC “simulate” masih terpasang di halaman ini (/api/kyc/simulate). | P15: 2026-06-09 | Q15: 2026-09-09
A16: 2.e.iv | B16: Akun & Identitas | C16: Tab | D16: Referral & Coin | E16: Quality Check | F16: Bagian dari Pengaturan akun (diubah 9 Sep). | G16: https://saloka.id/settings (tab dipilih di dalam halaman) | H16: Pengguna yang sudah login | I16: Link referral pribadi dan ringkasan koin. | M16: src/app/settings/page.tsx | P16: 2026-06-09 | Q16: 2026-09-09
A17: 2.e.v | B17: Akun & Identitas | C17: Tab | D17: Buku Alamat | E17: Quality Check | F17: Bagian dari Pengaturan akun (diubah 9 Sep). | G17: https://saloka.id/settings (tab dipilih di dalam halaman) | H17: Pengguna yang sudah login | I17: Alamat pengiriman yang tersimpan. | M17: src/app/settings/page.tsx | P17: 2026-06-09 | Q17: 2026-09-09
A18: 2.e.vi | B18: Akun & Identitas | C18: Tab | D18: Integrasi & WA Gateway | E18: Quality Check | F18: Bagian dari Pengaturan akun (diubah 9 Sep). | G18: https://saloka.id/settings (tab dipilih di dalam halaman) | H18: Pengguna yang sudah login | I18: Pengaturan WhatsApp gateway dan log pesan. | M18: src/app/settings/page.tsx | P18: 2026-06-09 | Q18: 2026-09-09
A19: 2.e.vii | B19: Akun & Identitas | C19: Tab | D19: Notifikasi | E19: Quality Check | F19: Bagian dari Pengaturan akun (diubah 9 Sep). | G19: https://saloka.id/settings (tab dipilih di dalam halaman) | H19: Pengguna yang sudah login | I19: Notifikasi apa saja yang diterima pengguna. | M19: src/app/settings/page.tsx | P19: 2026-06-09 | Q19: 2026-09-09
A20: 2.e.viii | B20: Akun & Identitas | C20: Tab | D20: Preferensi Tampilan | E20: Quality Check | F20: Bagian dari Pengaturan akun (diubah 9 Sep). | G20: https://saloka.id/settings (tab dipilih di dalam halaman) | H20: Pengguna yang sudah login | I20: Preferensi tampilan. | M20: src/app/settings/page.tsx | P20: 2026-06-09 | Q20: 2026-09-09
A21: 2.f | B21: Akun & Identitas | C21: Halaman | D21: Profil publik | E21: Quality Check | F21: Stabil sejak 29 Agu, tetapi ada tombol bypass KYC untuk uji coba di sini. | G21: https://saloka.id/profile/[user-id] | H21: Semua orang (pemilik melihat lebih banyak) | I21: Profil publik / mini storefront: produk, keanggotaan komunitas, total komisi, tombol kontak & bagikan. Link referral mengarah ke sini. | J21: Profil, produk, komunitas & peran, statistik affiliate, ringkasan wallet (pemilik) | K21: User, Order, Wallet, AffiliateReferral, CommunityMembership | L21: DataStore.getUserCommunitiesWithRoles, getAffiliateStats, getWalletByUserId; /api/kyc/didit | M21: src/app/profile/[id]/page.tsx; src/app/profile/[id]/ProfileViewerClient.tsx | O21: Tombol bypass KYC ditambahkan untuk uji coba (18 Jul): pastikan tersembunyi di production. | P21: 2026-05-30 | Q21: 2026-08-29
A22: 2.g | B22: Akun & Identitas | C22: Halaman | D22: Callback verifikasi KYC | E22: Quality Check | F22: Perbaikan keandalan di-commit 9 Sep; route uji coba masih ada. | G22: https://saloka.id/kyc/callback | H22: Pengguna yang kembali dari Didit | I22: Halaman setelah pengecekan identitas Didit: sedang diproses / berhasil / sedang ditinjau, lalu otomatis dialihkan. | J22: Status KYC per pengguna | K22: User (kycStatus) | L22: /api/kyc/didit; /api/kyc/status; /api/didit/webhook; /api/kyc/simulate | M22: src/app/kyc/callback/page.tsx; src/app/api/didit/webhook/route.ts | N22: Jalur paralel: Sistem Verifikasi | O22: Route uji coba /api/kyc/simulate masih ada; submitKycAction bisa menyetujui KYC tanpa pengecekan asli (tidak terhubung ke UI tetapi masih bisa dipanggil), ditunda ke Phase 6. | P22: 2026-06-20 | Q22: 2026-06-20 | T22: 1. Signature webhook Didit gagal, hasil KYC tidak pernah diterima 2. KYC crash karena field database hilang / error batas kredit Didit | U22: 1. — 2. — | V22: 1. Upgrade ke Didit V3 API, signature diperbaiki (b1d68d9) 2. Field ditambahkan, error ditangani (7a4a322) | W22: 1. 2026-07-11 2. 2026-07-18
A23: 2.h | B23: Akun & Identitas | C23: Alur | D23: Link pendek referral | E23: Quality Check | F23: Atribusi diperbaiki 13 Sep; perlu diuji ulang. | G23: https://saloka.id/ref/[username] | H23: Semua orang | I23: Mengarahkan pengunjung ke profil pemberi referral (atau ke produk, untuk link affiliate lama) dan menyimpan cookie referral first-touch selama 30 hari. | J23: Cookie referral, pelacakan klik | K23: User, AffiliateReferral | L23: src/app/ref/[slug]/route.ts; affiliate-extra.trackAffiliateClick | M23: src/app/ref/[slug]/route.ts | P23: 2026-09-13 | Q23: 2026-09-13 | AF23: Atribusi referral rusak (pengguna baru tidak terhubung ke pemberi referral) | AG23: — | AH23: Atribusi diperbaiki (1c4c28b) | AI23: 2026-09-13
A24: 3 | B24: Marketplace (Produk) | C24: Fitur | D24: Marketplace (Produk) | E24: Sedang Berjalan | F24: Penjelajahan & halaman produk berjalan; alur pesanan → pembayaran → pengiriman adalah pekerjaan Minggu C dan belum selesai.
A25: 3.a | B25: Marketplace (Produk) | C25: Halaman | D25: Daftar produk Marketplace | E25: Quality Check | F25: Tata letak mobile diperbaiki 1 Sep. | G25: https://saloka.id/market | H25: Semua orang | I25: Katalog produk dengan pencarian, filter kategori, dan urutan. | J25: Produk & info merchant | K25: Product, User | L25: products.getProducts | M25: src/app/market/page.tsx; src/app/market/ProductListGrid.tsx | P25: 2026-05-30 | Q25: 2026-09-01 | T25: Daftar produk crash pada beberapa pencarian (field kosong / indeks negatif) | U25: — | V25: Pencarian & grid dibuat null-safe (25a6964, 5677ae8) | W25: 2026-06-21 | AB25: Tata letak mobile melebihi layar | AC25: — | AD25: Tata letak mobile & padding header diperbaiki (24fa1ed) | AE25: 2026-09-01
A26: 3.b | B26: Marketplace (Produk) | C26: Halaman | D26: Detail produk | E26: Quality Check | F26: Didesain ulang 12 Sep (varian, sticky buy box). | G26: https://saloka.id/market/product/[product-id] | H26: Semua orang (membeli perlu login) | I26: Halaman produk: galeri foto, varian, sticky buy box, tab deskripsi/ulasan, ulasan, chat dengan penjual. | J26: Produk, varian, stok, ulasan | K26: Product, ProductReview, User, Notification | L26: products.getProductById; reviews.createReview, getProductReviews; /api/products/[id]/reviews-check | M26: src/app/market/product/[id]/ProductDetailView.tsx; src/lib/product-variants.ts | O26: Varian disimpan sebagai JSON tersembunyi di dalam deskripsi produk, bukan di tabel tersendiri. | P26: 2026-09-12 | Q26: 2026-09-12
A27: 3.c | B27: Marketplace (Produk) | C27: Halaman | D27: Keranjang & Checkout | E27: Sedang Berjalan | F27: Checkout berjalan; Snackbox kini digabung ke payload pesanan yang sama. Diverifikasi ulang 30 Sep. | G27: https://saloka.id/cart | H27: Semua orang (checkout perlu login) | I27: Keranjang bersama untuk Marketplace dan Snackbox: alamat, tarif kurir (Biteship), rincian biaya, bayar dengan DOKU (QRIS / virtual account) atau wallet; membuat pesanan. | J27: Isi keranjang (browser), ongkos kirim, pesanan, status pembayaran | K27: Order, OrderItem, OrderTracking, Product, Wallet, WalletTransaction, AffiliateReferral, Notification | L27: wallet-affiliate.checkoutCart, getActivePaymentMethods; /api/shipping/destination, /api/shipping/calculate; /api/doku/direct, /api/doku/verify; /api/midtrans/verify (legacy) | M27: src/app/cart/page.tsx; src/components/DokuDirectPaymentModal.tsx | N27: Minggu C (14–20 Sep): alur pesanan → pembayaran → pengiriman | O27: Jalur Midtrans/Komerce dan tombol bypass sandbox sudah dihapus. Sisa: pembagian komisi affiliate 60/10/10/20 masih hardcoded di kode; pelacakan pengiriman belum otomatis. | P27: 2026-05-30 | Q27: 2026-09-12 | T27: 1. Tamu bisa masuk ke checkout tanpa login 2. Total checkout menyembunyikan biaya admin/layanan 3. Pembuatan pesanan gagal saat koneksi database lambat | U27: 1. — 2. — 3. — | V27: 1. Wajib login sebelum checkout + banner untuk tamu (a1b5254) 2. Rincian biaya ditampilkan di total (527f891) 3. Timeout koneksi diperpanjang + pencatatan error (bd4a4cb, 86a6148) | W27: 1. 2026-08-15 2. 2026-08-15 3. 2026-08-15 | AF27: Menutup modal pembayaran membuka halaman 404 | AG27: — | AH27: Penutupan modal ditangani (cb6ff56) | AI27: 2026-09-12
A28: 3.d | B28: Marketplace (Produk) | C28: Halaman | D28: Pesanan saya | E28: Quality Check | F28: Tampilan diperbarui 12 Sep. | G28: https://saloka.id/orders | H28: Pembeli yang sudah login | I28: Daftar pesanan pembeli dengan badge status. | J28: Pesanan & status | K28: Order | L28: orders.getMyOrders | M28: src/app/orders/page.tsx | P28: 2026-05-31 | Q28: 2026-09-12 | AF28: Indikator status pesanan di daftar kurang jelas | AG28: — | AH28: Badge status diperbarui (9e46c12) | AI28: 2026-09-12
A29: 3.e | B29: Marketplace (Produk) | C29: Halaman | D29: Detail & pelacakan pesanan | E29: Sedang Berjalan | F29: Halaman berjalan; pelacakan kurir belum tersambung (diverifikasi 30 Sep). | G29: https://saloka.id/orders/[order-id] | H29: Pembeli pesanan tersebut | I29: Stepper status (dibayar → disiapkan → dikirim → diterima), riwayat pelacakan, konfirmasi pesanan diterima, tulis ulasan. | J29: Pesanan, tahapan pelacakan, ulasan | K29: Order, OrderTracking, ProductReview, Wallet | L29: orders.getOrderDetail; reviews.createReview | M29: src/app/orders/[id]/page.tsx | N29: Minggu C: sinkronisasi status kurir | O29: Pelacakan diperbarui manual oleh merchant (input resi + ubah status). trackBiteshipWaybill ada tapi tidak dipanggil; belum ada webhook Biteship. Notifikasi WA status pesanan memakai nomor penerima hardcoded (orders.ts:138). | P29: 2026-05-31 | Q29: 2026-09-12
A30: 3.f | B30: Marketplace (Produk) | C30: Halaman | D30: Invoice pesanan | E30: Selesai | F30: Stabil sejak 29 Agu untuk cakupan saat ini; field pajak adalah jalur terpisah. | G30: https://saloka.id/orders/[order-id]/invoice | H30: Pembeli / merchant pesanan tersebut | I30: Invoice yang bisa dicetak. | J30: Pesanan, pembeli, merchant, total | K30: Order, User | L30: orders.getOrderInvoiceData | M30: src/app/orders/[id]/invoice/page.tsx | N30: Jalur paralel: Pajak (PPN / e-Faktur) — belum dimulai | O30: Belum ada field PPN / e-Faktur. | P30: 2026-05-31 | Q30: 2026-08-29
A31: 3.g | B31: Marketplace (Produk) | C31: Halaman Admin | D31: Admin · Katalog Produk | E31: Quality Check | F31: CMS direstrukturisasi 5 Sep. | G31: https://saloka.id/cms_admin/products | H31: Admin dengan izin “products” | I31: Moderasi katalog produk. | J31: Semua produk | K31: Product | L31: src/app/cms_admin/components/ProductsTab.tsx | M31: src/app/cms_admin/components/ProductsTab.tsx | P31: 2026-09-05 | Q31: 2026-09-05
A32: 4 | B32: Jasa | C32: Fitur | D32: Jasa | E32: Sedang Berjalan | F32: Daftar dan booking berjalan, tetapi ulasan tidak disimpan ke database dan production bisa menampilkan jasa contoh.
A33: 4.a | B33: Jasa | C33: Halaman | D33: Daftar jasa | E33: Sedang Berjalan | F33: Jalur data asli ada, tetapi production bisa fallback ke jasa contoh. | G33: https://saloka.id/jasa | H33: Semua orang | I33: Katalog jasa dengan pencarian dan filter. | J33: Jasa & penyedia | K33: Service, User | L33: services.getServicesAction | M33: src/app/jasa/JasaClient.tsx; src/app/jasa/page.tsx | O33: Fallback ke jasa contoh (mock-seed) jika database tidak mengembalikan data. | P33: 2026-08-15 | Q33: 2026-09-05 | AB33: Daftar jasa kosong di production | AC33: — | AD33: Fallback ke jasa contoh (a06f595) | AE33: 2026-09-05
A34: 4.b | B34: Jasa | C34: Halaman | D34: Detail & booking jasa | E34: Sedang Berjalan | F34: Booking berjalan; ulasan jasa hanya tersimpan di memori server. | G34: https://saloka.id/jasa/[service-id] | H34: Semua orang (booking perlu login) | I34: Detail dan booking jasa: kalender bulanan, satu tanggal atau rentang tanggal, durasi, biaya platform sesuai durasi, ulasan. | J34: Jasa, ketersediaan, booking, ulasan | K34: Service, ServiceAvailability, ServiceBooking, AuditLog | L34: services.getServiceByIdAction, getServiceAvailabilityAction, createServiceBookingAction, getServiceReviewsAction, submitServiceReviewAction | M34: src/app/jasa/[id]/ServiceBookingClient.tsx; src/app/jasa/[id]/page.tsx | O34: Ulasan jasa tidak punya tabel database (disimpan di memori server, hilang saat restart). | P34: 2026-08-15 | Q34: 2026-09-05 | AB34: Biaya platform tidak menyesuaikan durasi booking; booking rentang tanggal tidak tersedia untuk beberapa tipe jasa | AC34: — | AD34: Biaya sesuai durasi; rentang tanggal untuk semua tipe (0b50861, 9eb0129) | AE34: 2026-09-05
A35: 4.c | B35: Jasa | C35: Halaman Admin | D35: Admin · Jasa & Layanan | E35: Quality Check | F35: 2 dari 3 tab sudah dibuat. | G35: https://saloka.id/cms_admin/services/katalog | H35: Admin dengan izin “services” | I35: Katalog jasa, booking, dan jadwal. | J35: Jasa, booking | K35: Service, ServiceBooking | M35: src/app/cms_admin/components/ServicesTab.tsx | P35: 2026-09-05 | Q35: 2026-09-05
A36: 4.c.i | B36: Jasa | C36: Tab Admin | D36: Katalog Jasa | E36: Quality Check | F36: Sudah dibuat; CMS direstrukturisasi 5 Sep. | G36: https://saloka.id/cms_admin/services/katalog
A37: 4.c.ii | B37: Jasa | C37: Tab Admin | D37: Booking | E37: Quality Check | F37: Sudah dibuat; CMS direstrukturisasi 5 Sep. | G37: https://saloka.id/cms_admin/services/booking
A38: 4.c.iii | B38: Jasa | C38: Tab Admin | D38: Jadwal | E38: Belum Dimulai | F38: Menampilkan layar “belum tersedia”. | G38: https://saloka.id/cms_admin/services/jadwal | O38: Belum ada kalender ketersediaan lintas jasa untuk admin.
A39: 5 | B39: Snackbox | C39: Fitur | D39: Snackbox | E39: Sedang Berjalan | F39: Halaman pelanggan & checkout (digabung ke pesanan Marketplace) berjalan; 3 layar admin masih mock; v1 belum dinyatakan rilis (diverifikasi 30 Sep).
A40: 5.a | B40: Snackbox | C40: Halaman | D40: Halaman Snackbox | E40: Quality Check | F40: Perombakan besar 9 Sep; QA v1 / bug bash belum terdokumentasi. | G40: https://saloka.id/snackbox | H40: Semua orang | I40: Pemesanan snack box lokal: deteksi kelurahan lewat GPS/IP (deteksi ulang saat pengguna berpindah), pencarian kelurahan, tab kategori, produk dari merchant di area tersebut, sticky cart bar, CTA pendaftaran merchant. | J40: Lokasi terdeteksi (browser), kelurahan, produk Snackbox | K40: Product, User | L40: products.getSnackboxProducts; /api/geolocation/detect, /api/geolocation/reverse (ip-api + OpenStreetMap); /api/kelurahan/search (kodepos.vercel.app) | M40: src/app/snackbox/page.tsx; src/context/SnackboxContext.tsx; src/components/snackbox/ | N40: Minggu A (1–6 Sep): Snackbox v1 | O40: Rilis v1 belum dinyatakan; belum ada bug bash terdokumentasi; slider bagi hasil 15–20% dan pencarian kategori merchant belum di-QA; daftar kelurahan fallback ke data mock jika API kode pos gagal. | P40: 2026-08-29 | Q40: 2026-09-09 | AB40: Lokasi GPS kurang presisi dibanding onboarding; masalah tata letak mobile | AC40: — | AD40: Reverse-geocoding sama dengan onboarding; tata letak mobile diperbaiki (8133e77) | AE40: 2026-09-05
...

Sheet Panduan
A1: Cara membaca workbook ini
A2: Satu baris untuk setiap fitur (hijau), halaman, tab, layar admin (CMS), alur di balik layar, atau komponen di seluruh situs saloka.id. Disusun dari repository kode pada 13 Sep 2026.
A3: Gunakan filter di baris 2 sheet “Pelacak Fitur” (misalnya filter Fitur atau Status), atau tombol +/− di sisi kiri untuk menutup/membuka halaman dan tab.
A4: Status (dropdown di kolom E)
A5: Selesai — dibangun dengan data asli, tidak ditemukan kekurangan di kode, tidak ada perbaikan dalam 2 minggu terakhir.
A6: Quality Check — dibangun dengan data asli, tetapi baru diubah/diperbaiki atau masih menunggu persetujuan QA.
A7: Sedang Berjalan — baru sebagian dibangun, memakai data mock/contoh, atau masih ada bagian yang kurang.
A8: Belum Dimulai — hanya ada layar placeholder (misalnya “Segera Hadir”).
A9: Status disimpulkan dari kode, riwayat commit, roadmap September 2026, dan catatan progres mingguan — bukan dari pengujian langsung di situs. Mohon ditinjau, dengan melihat kolom “Alasan status”.
A10: Level
A11: Fitur → Halaman / Halaman Admin / Alur / Komponen → Tab / Tab Admin. Alur = proses di balik layar tanpa halaman sendiri (misalnya pembayaran DOKU). Komponen = elemen yang tampil di seluruh situs (misalnya kolom pencarian).
A12: Baris Komunitas menyebutkan tipe komunitas (Perkumpulan atau Koperasi) serta tier atau template yang berlaku di kolom “Siapa yang bisa akses”.
... A23: “Phase 6” merujuk pada pekerjaan komunitas yang ditunda (pencairan pinjaman, transfer SHU ke wallet, penagihan tier, dll.) yang tercantum di PHASE6_TODO.md.
